Workbook

Sheet Overview
B2: Project Summary | E2: Returns
B3: Deal Name | C3: =Assumptions!C3 -> 6719 N Lamar BLVD | E3: Net Profit | G3: ='Draw Schedule'!D171 -> 4992185.3
B4: Address | C4: =Assumptions!C4 -> 6719 N Lamar BLVD | E4: Equity Multiple | G4: ='Draw Schedule'!D172 -> 1.6615642
B5: City/State/Zip | C5: =Assumptions!C5 -> Austin, TX | E5: IRR | G5: ='Draw Schedule'!D173 -> 0.086374065
B6: Neighborhood | C6: =Assumptions!C6 -> 0 | E6: Stabilized Yield on Cost | G6: ='Net CF Post TCO'!D33 -> 0.053028021
B7: Lot Size | C7: =Assumptions!F13 -> 0
B8: Gross Building SF | C8: =Assumptions!D20 -> 106058.78
B9: Net Building SF | C9: =C11+C10 -> 53151
B10: Net Retail SF | C10: =Assumptions!F16 -> 4400
B11: Net Residential SF | C11: =Assumptions!F17 -> 48751
B12: Residentail Units | C12: =Assumptions!C29 -> 66
B13: Parking Spaces | C13: =Assumptions!F32 -> 63
B14: Project Timeline | C14: =Assumptions!J12+Assumptions!F36+Assumptions!F37 -> 83
B15: Trending? | C15: =Assumptions!L8 -> Yes
B16: Ground Lease? | C16: =Assumptions!Q24 -> No
B18: Sources & Uses
B19: Uses | C19: Total | D19: =Assumptions!U3 -> % | E19: =Assumptions!V3 -> $/GSF | F19: =Assumptions!W3 -> $/NSF | G19: =Assumptions!X3 -> $/Unit
B20: =Assumptions!S4 -> Site Acquisition | C20: =Assumptions!T4 -> 3500000 | D20: =Assumptions!U4 -> 0.11595496 | E20: =Assumptions!V4 -> 33.000569 | F20: =Assumptions!W4 -> 65.850125 | G20: =Assumptions!X4 -> 53030.303
B21: =Assumptions!S5 -> Hard Costs | C21: =Assumptions!T5 -> 19519500 | D21: =Assumptions!U5 -> 0.6466808 | E21: =Assumptions!V5 -> 184.04417 | F21: =Assumptions!W5 -> 367.24615 | G21: =Assumptions!X5 -> 295750
B22: =Assumptions!S6 -> Soft Costs | C22: =Assumptions!T6 -> 5033193.3 | D22: =Assumptions!U6 -> 0.16674963 | E22: =Assumptions!V6 -> 47.456641 | F22: =Assumptions!W6 -> 94.696117 | G22: =Assumptions!X6 -> 76260.505
B23: =Assumptions!S7 -> DS/GL Reserve | C23: =Assumptions!T7 -> 2131440.8 | D23: =Assumptions!U7 -> 0.070614609 | E23: =Assumptions!V7 -> 20.096789 | F23: =Assumptions!W7 -> 40.101613 | G23: =Assumptions!X7 -> 32294.558
B24: =Assumptions!S8 -> NOI Shortfall | C24: =Assumptions!T8 -> 0 | D24: =Assumptions!U8 -> 0 | E24: =Assumptions!V8 -> 0 | F24: =Assumptions!W8 -> 0 | G24: =Assumptions!X8 -> 0
B25: =Assumptions!S9 -> Total Uses | C25: =Assumptions!T9 -> 30184134 | D25: =Assumptions!U9 -> 1 | E25: =Assumptions!V9 -> 284.59817 | F25: =Assumptions!W9 -> 567.894 | G25: =Assumptions!X9 -> 457335.37
B27: =Assumptions!S17 -> Equity | C27: =Assumptions!T17 -> 7546033.5 | D27: =Assumptions!U17 -> 0.25 | E27: =Assumptions!V17 -> 71.149543 | F27: =Assumptions!W17 -> 141.9735 | G27: =Assumptions!X17 -> 114333.84
B28: =Assumptions!S13 -> Acquisition Loan | C28: =Assumptions!T13 -> 1750000 | D28: =Assumptions!U13 -> 0.057977479 | E28: =Assumptions!V13 -> 16.500284 | F28: =Assumptions!W13 -> 32.925063 | G28: =Assumptions!X13 -> 26515.152
B29: =Assumptions!S14 -> Construction Loan | C29: =Assumptions!T14 -> 20888101 | D29: =Assumptions!U14 -> 0.69202252 | E29: =Assumptions!V14 -> 196.94834 | F29: =Assumptions!W14 -> 392.99544 | G29: =Assumptions!X14 -> 316486.37
B30: =Assumptions!S15 -> Mezz Loan | C30: =Assumptions!T15 -> 0 | D30: =Assumptions!U15 -> 0 | E30: =Assumptions!V15 -> 0 | F30: =Assumptions!W15 -> 0 | G30: =Assumptions!X15 -> 0
B31: =Assumptions!S16 -> Ground Lease | C31: =Assumptions!T16 -> 0 | D31: =Assumptions!U16 -> 0 | E31: =Assumptions!V16 -> 0 | F31: =Assumptions!W16 -> 0 | G31: =Assumptions!X16 -> 0
B32: =Assumptions!S18 -> Total Sourses | C32: =SUM(C27:C31) -> 30184134 | D32: =SUM(D27:D31) -> 1 | E32: =SUM(E27:E31) -> 284.59817 | F32: =SUM(F27:F31) -> 567.894 | G32: =SUM(G27:G31) -> 457335.37

Sheet Assumptions
B2: Deal Info | H2: Rent Assumptions | N2: Financing | S2: Uses
B3: Deal Name | C3: 6719 N Lamar BLVD | I3: Margin | K3: Rent | L3: Growth | N3: Acquisition Loan | T3: $ | U3: % | V3: $/GSF | W3: $/NSF | X3: $/Unit
B4: Address | C4: 6719 N Lamar BLVD | H4: Residential | J4: $/NSF | K4: ='Unit Mix'!I24 -> 3.2694304 | L4: 0.03 | N4: Proceeds | Q4: =F9*Q6 -> 1750000 | S4: Site Acquisition | T4: =F9 -> 3500000 | U4: =T4/$T$9 -> 0.11595496 | V4: =T4/Assumptions!$D$20 -> 33.000569 | W4: =T4/$F$20 -> 65.850125 | X4: =T4/$C$29 -> 53030.303
B5: City/State/Zip | C5: Austin, TX | H5: Retail | J5: $/NSF | K5: 2.7 | L5: 0.03 | N5: Intro Month | P5: =EDATE($F$35,Q5) -> 46023 | Q5: 0 | S5: Hard Costs | T5: ='Construction Costs'!E11 -> 19519500 | U5: =T5/$T$9 -> 0.6466808 | V5: =T5/Assumptions!$D$20 -> 184.04417 | W5: =T5/$F$20 -> 367.24615 | X5: =T5/$C$29 -> 295750
B6: Neighborhood | H6: Parking Spaces | I6: 1 | J6: $/Space/Mo | K6: 0 | L6: 0.03 | N6: LTC (Land) | Q6: 0.5 | S6: Soft Costs | T6: ='Construction Costs'!E36-T7-T8 -> 5033193.3 | U6: =T6/$T$9 -> 0.16674963 | V6: =T6/Assumptions!$D$20 -> 47.456641 | W6: =T6/$F$20 -> 94.696117 | X6: =T6/$C$29 -> 76260.505
H7: Misc. Income | J7: $/Unit/Mo | K7: 150 | L7: 0.03 | N7: Interest Rate | Q7: 0.06 | S7: DS/GL Reserve | T7: =-'Draw Schedule'!D16-'Draw Schedule'!D15 -> 2131440.8 | U7: =T7/$T$9 -> 0.070614609 | V7: =T7/Assumptions!$D$20 -> 20.096789 | W7: =T7/$F$20 -> 40.101613 | X7: =T7/$C$29 -> 32294.558
B8: Acquisition | H8: Trended? | K8: Y/N | L8: Yes | N8: Takeout Month | P8: =EDATE($F$35,Q8) -> 46631 | Q8: 20 | S8: NOI Shortfall | T8: =-'Draw Schedule'!D14 -> 0 | U8: =T8/$T$9 -> 0 | V8: =T8/Assumptions!$D$20 -> 0 | W8: =T8/$F$20 -> 0 | X8: =T8/$C$29 -> 0
B9: Land Price | F9: 3500000 | S9: Total Uses | T9: =SUM(T4:T8) -> 30184134 | U9: =T9/$T$9 -> 1 | V9: =T9/Assumptions!$D$20 -> 284.59817 | W9: =T9/$F$20 -> 567.894 | X9: =T9/$C$29 -> 457335.37
B10: Land Price (Per Unit) | F10: =F9/C29 -> 53030.303 | H10: Sale Assumptions (Fee Simple) | N10: Construction Loan
I11: Sale Month Post TCO | K11: Cap Rate | L11: Sale Cost | N11: Proceeds | Q11: =IF(Q24="No",T9*Q13-Q4,Q13*(T9-T4)) -> 20888101 | S11: Sources
B12: Size Metrics | H12: Residential | J12: 48 | K12: 0.05 | L12: 0.01 | N12: Intro Month | P12: =EDATE($F$35,Q12) -> 46569 | Q12: 18 | T12: $ | U12: % | V12: $/GSF | W12: $/NSF | X12: $/Unit
B13: Land | H13: Retail | J13: 48 | K13: 0.055 | L13: 0.035 | N13: LTC | Q13: 0.75 | S13: Acquisition Loan | T13: =Q4 -> 1750000 | U13: =T13/$T$18 -> 0.057977479 | V13: =T13/D$20 -> 16.500284 | W13: =T13/$F$20 -> 32.925063 | X13: =T13/$C$29 -> 26515.152
B14: Stories | N14: Interest Rate | Q14: 0.075 | S14: Construction Loan | T14: =Q11 -> 20888101 | U14: =T14/$T$18 -> 0.69202252 | V14: =T14/D$20 -> 196.94834 | W14: =T14/$F$20 -> 392.99544 | X14: =T14/$C$29 -> 316486.37
D15: GSF | E15: Efficiency | F15: NSF | H15: Lease Up Schedule | S15: Mezz Loan | T15: =Q17 -> 0 | U15: =T15/$T$18 -> 0 | V15: =T15/D$20 -> 0 | W15: =T15/$F$20 -> 0 | X15: =T15/$C$29 -> 0
B16: Retail | D16: 4400 | E16: 1 | F16: =D16*E16 -> 4400 | K16: Resi | L16: Retail | N16: Mezz Loan | S16: Ground Lease | T16: =IF(Q24="Yes",Q25,0) -> 0 | U16: =T16/$T$18 -> 0 | V16: =T16/D$20 -> 0 | W16: =T16/$F$20 -> 0 | X16: =T16/$C$29 -> 0
B17: Residential | D17: =F17/0.9 -> 54167.778 | E17: =F17/D17 -> 0.9 | F17: =F29 -> 48751 | H17: Occupancy at TCO | K17: 0.35 | L17: 0.5 | N17: Proceeds | Q17: =T9*Q19 -> 0 | S17: Equity | T17: =T9-SUM(T13:T16) -> 7546033.5 | U17: =T17/$T$18 -> 0.25 | V17: =T17/D$20 -> 71.149543 | W17: =T17/$F$20 -> 141.9735 | X17: =T17/$C$29 -> 114333.84
B18: Structured Parking | D18: 34000 | E18: 0 | F18: =D18*E18 -> 0 | H18: Lease Up Per Month Post TCO | K18: 0.1 | L18: 0.15 | N18: Intro Month | P18: =EDATE($F$35,Q18) -> 46388 | Q18: 12 | S18: Total Sourses | T18: =SUM(T13:T17) -> 30184134 | U18: =T18/$T$18 -> 1 | V18: =T18/D$20 -> 284.59817 | W18: =T18/$F$20 -> 567.894 | X18: =T18/$C$29 -> 457335.37
B19: Amenity / Circ. BOH | D19: =11345+2146 -> 13491 | E19: 0 | F19: =D19*E19 -> 0 | H19: Stabilized Occupancy | K19: 0.95 | L19: 1 | N19: LTC | Q19: 0 | S19: Check | T19: =T18+'Draw Schedule'!D17+T9-'Draw Schedule'!D24 -> 0.00022627413
B20: Total | D20: =SUM(D16:D19) -> 106058.78 | E20: =F20/D20 -> 0.50114664 | F20: =SUM(F16:F19) -> 53151 | N20: Interest Rate | Q20: 0.12
H21: Operating Assumptions
B22: Unit Mix / Parking Spaces | H22: Utilities | J22: $/Unit | K22: 800 | L22: =K22*$C$29 -> 52800 | N22: Ground Lease
C23: # | D23: % | E23: Avg. SF | F23: Total SF | H23: Repairs and Maintenance | J23: $/Unit | K23: 500 | L23: =K23*$C$29 -> 33000 | N23: Ground Lease
B24: Studio | C24: ='Unit Mix'!C6+'Unit Mix'!C15 -> 0 | D24: =C24/$C$29 -> 0 | E24: =F24/C24 -> #DIV/0! | F24: ='Unit Mix'!F6+'Unit Mix'!F15 -> 0 | H24: Labor | J24: $/Unit | K24: 900 | L24: =K24*$C$29 -> 59400 | N24: GL? | P24: Y/N | Q24: No
B25: 1 BR | C25: ='Unit Mix'!C30+'Unit Mix'!C31+'Unit Mix'!C32+'Unit Mix'!C38 -> 24 | D25: =C25/$C$29 -> 0.36363636 | E25: =F25/C25 -> 583.375 | F25: ='Unit Mix'!E30+'Unit Mix'!E31+'Unit Mix'!E32+'Unit Mix'!E38 -> 14001 | H25: Insurance | J25: $/Unit | K25: 350 | L25: =K25*$C$29 -> 23100 | N25: Proceeds | Q25: 0
B26: 2 BR | C26: ='Unit Mix'!C33+'Unit Mix'!C34+'Unit Mix'!C39 -> 42 | D26: =C26/$C$29 -> 0.63636364 | E26: =F26/C26 -> 827.38095 | F26: ='Unit Mix'!E33+'Unit Mix'!E34+'Unit Mix'!E39 -> 34750 | H26: G&A / Service Contracts | J26: $/Unit | K26: 350 | L26: =K26*$C$29 -> 23100 | N26: Intro Month | P26: =EDATE($F$35,Q26) -> 46023 | Q26: 0
B27: 3 BR | C27: 0 | D27: =C27/$C$29 -> 0 | E27: 1200 | F27: =E27*C27 -> 0 | H27: Marketing/Leasing | J27: $/Unit | K27: 300 | L27: =K27*$C$29 -> 19800 | N27: Growth Rate | Q27: 0.02
B28: 4 BR | C28: 0 | D28: =C28/$C$29 -> 0 | E28: 1400 | F28: =E28*C28 -> 0 | H28: Turnover | J28: $/Unit | K28: 0 | L28: =K28*$C$29 -> 0 | N28: LTC | Q28: =Q25/T9 -> 0
B29: Total / Avg. | C29: =SUM(C24:C28) -> 66 | D29: =C29/$C$29 -> 1 | E29: =F29/C29 -> 738.65152 | F29: =SUM(F24:F28) -> 48751 | H29: Capital Reserves | J29: $/Unit | K29: 100 | L29: =K29*$C$29 -> 6600 | N29: Ground Lease Rent | Q29: 0.048
B30: Residential Parking Spaces | F30: 63 | H30: Management Fee | J30: %/GI | K30: 0.02 | N30: Cap Rate Increase | Q30: 0.0025
B31: Retail Parking Spaces | F31: 0 | H31: Opex Contingency | J31: %/OE | K31: 0.025
B32: Total Parking Spaces | E32: =(D18+D19)/F32 -> 753.8254 | F32: =SUM(F30:F31) -> 63 | H32: Annual Expense Increase | K32: =L4 -> 0.03 | N32: Refinance Loan
H33: Asset Management Fee | K33: 0.01 | N33: Refi? | P33: Y/N | Q33: No
B34: Key Timing | H34: Concessions | N34: DSCR or Debt Yield | Q34: DSCR
B35: Model Start Date* | F35: 46023 | H35: Retail Months Free | L35: 2 | N35: Interest Only or Amortizing | Q35: Amortizing
B36: Preconstruction (in Months) | F36: 15 | H36: Resi Months Free | L36: 1 | N36: Intro Month Post TCO | P36: =EDATE($F$38,Q36) -> 47453 | Q36: 12 | R36: *Must be multiple of 12
B37: Construction (in Month) | F37: 20 | H37: Real Estate Taxes | N37: Proceeds | Q37: =IF(Q33="Yes",IF(Q34="DSCR",-PV(Q41,Q42,Q44/Q40),Q44/Q43),0) -> 0
B38: TCO Date | F38: =EDATE(F35,(F36+F37)) -> 47088 | H38: Payment (Calc on Other Tab) | K38: $ | L38: =Taxes!E28 -> 432399.64 | N38: Closing Costs | Q38: =-'Closing Costs'!E53 -> 0
B39: Resi Stabilization Date | F39: =EDATE(F38,ROUNDUP((K19-K17)/K18,0)) -> 47270 | H39: Assessment as % of Construction | K39: % | L39: =Taxes!E9 -> 0.7 | N39: Net Proceeds | Q39: =SUM(Q37:Q38) -> 0
B40: Resi Sales Date | F40: =EDATE($F$38,J12) -> 48549 | H40: Tax Rate | K40: % | L40: =Taxes!E26/100 -> 0.02046485 | N40: DSCR | Q40: 1.2
B41: Retail Sales Date | F41: =EDATE($F$38,J13) -> 48549 | H41: Early Payment Discount | L41: 0.04 | N41: Interest Rate | Q41: 0.0375
...

Sheet Unit Mix
B2: MARKET RATE UNIT MIX
E4: Avg Unit | F4: Total | G4: Unit Monthly | H4: Yearly | I4: Monthly | J4: Monthly | K4: Misc Income
B5: Description | C5: # of Units | D5: % of Total | E5: Sq. Ft. | F5: Rentable Area | G5: Avg. Rent | H5: Avg. Unit Rent/SF | I5: Avg. Unit Rent/SF | J5: Income | K5: Per Unit/mo
B6: Studio | C6: 0 | D6: =+C6/$C$9 -> 0 | E6: 384 | F6: =E6*C6 -> 0 | G6: 1500 | H6: =G6*12/E6 -> 46.875 | I6: =H6/12 -> 3.90625 | J6: =C6*G6 -> 0 | K6: 0 | M6: 35
B7: 1 | C7: 86 | D7: =+C7/$C$9 -> 0.68253968 | E7: 730 | F7: =E7*C7 -> 62780 | G7: 1950 | H7: =G7*12/E7 -> 32.054795 | I7: =H7/12 -> 2.6712329 | J7: =C7*G7 -> 167700 | K7: 0 | M7: 85
B8: 2 | C8: 40 | D8: =+C8/$C$9 -> 0.31746032 | E8: 1100 | F8: =E8*C8 -> 44000 | G8: 2850 | H8: =G8*12/E8 -> 31.090909 | I8: =H8/12 -> 2.5909091 | J8: =C8*G8 -> 114000 | K8: 0 | M8: 35
B9: Total | C9: =SUM(C6:C8) -> 126 | D9: =+C9/$C$9 -> 1 | E9: =SUMPRODUCT(E6:E8,C6:C8)/C9 -> 847.46032 | F9: =SUM(F6:F8) -> 106780 | G9: =SUMPRODUCT(G6:G8,C6:C8)/C9 -> 2235.7143 | H9: =G9*12/E9 -> 31.657614 | I9: =H9/12 -> 2.6381345 | J9: =SUM(J6:J8) -> 281700 | K9: =SUMPRODUCT(K6:K8,$C$6:$C$8)/$C$9 -> 0
B11: AFFORDABLE HOUSING UNIT MIX - 60% AMI
E13: Avg Unit | F13: Total | G13: Unit Monthly | H13: Yearly | I13: Monthly | J13: Monthly | K13: Misc Income
B14: Description | C14: # of Units | D14: % of Total | E14: Sq. Ft. | F14: Rentable Area | G14: Avg. Rent | H14: Avg. Unit Rent/SF | I14: Avg. Unit Rent/SF | J14: Income | K14: Per Unit/mo
B15: Studio | C15: 0 | D15: =+C15/$C$18 -> 0 | E15: =E6 -> 384 | F15: =E15*C15 -> 0 | G15: =1159*1.05 -> 1216.95 | H15: =G15*12/E15 -> 38.029688 | I15: =H15/12 -> 3.1691406 | J15: =C15*G15 -> 0 | K15: 0 | M15: =M6*0.12 -> 4.2
B16: 1 | C16: 10 | D16: =+C16/$C$18 -> 0.58823529 | E16: 730 | F16: =E16*C16 -> 7300 | G16: =1159*1.05 -> 1216.95 | H16: =G16*12/E16 -> 20.004658 | I16: =H16/12 -> 1.6670548 | J16: =C16*G16 -> 12169.5 | K16: 0 | M16: =M7*0.12 -> 10.2
B17: 2 | C17: 7 | D17: =+C17/$C$18 -> 0.41176471 | E17: =E8 -> 1100 | F17: =E17*C17 -> 7700 | G17: =1324*1.05 -> 1390.2 | H17: =G17*12/E17 -> 15.165818 | I17: =H17/12 -> 1.2638182 | J17: =C17*G17 -> 9731.4 | K17: 0 | M17: =M8*0.12 -> 4.2
B18: Total | C18: =SUM(C15:C17) -> 17 | D18: =+C18/$C$18 -> 1 | E18: =SUMPRODUCT(E15:E17,C15:C17)/C18 -> 882.35294 | F18: =SUM(F15:F17) -> 15000 | G18: =SUMPRODUCT(G15:G17,C15:C17)/C18 -> 1288.2882 | H18: =G18*12/E18 -> 17.52072 | I18: =H18/12 -> 1.46006 | J18: =SUM(J15:J17) -> 21900.9 | K18: =SUMPRODUCT(K15:K17,$C$15:$C$17)/$C$18 -> 0
C21: Units | D21: % | E21: NSF | F21: % | G21: $ | H21: $/PSF | I21: $/PSF
B22: Market | C22: =C35 -> 60 | D22: =C22/$C$24 -> 0.90909091 | E22: =E35 -> 44181 | F22: =E22/$E$24 -> 0.90625833 | G22: =H35 -> 1813200 | H22: =G22/E22 -> 41.040266 | I22: =H22/12 -> 3.4200222
B23: AH (60%) | C23: =C40 -> 6 | D23: =C23/$C$24 -> 0.090909091 | E23: =E40 -> 4570 | F23: =E23/$E$24 -> 0.093741667 | G23: =H40 -> 99456 | H23: =G23/E23 -> 21.762801 | I23: =H23/12 -> 1.8135667
B24: Total | C24: =C22+C23 -> 66 | D24: =C24/$C$24 -> 1 | E24: =SUM(E22:E23) -> 48751 | F24: =E24/$E$24 -> 1 | G24: =SUM(G22:G23) -> 1912656 | H24: =G24/E24 -> 39.233164 | I24: =H24/12 -> 3.2694304
E25: =E24/C24 -> 738.65152
B28: Free market
B29: Condo Project | C29: # Units | D29: Avg SF | E29: Total SF | F29: Rent | G29: Total Rent income | H29: Yearly income | I29: yearly psf | J29: Montly $/SF
B30: 1BR – A (Compact) | C30: 1 | D30: 546 | E30: =C30*D30 -> 546 | F30: 1850 | G30: =F30*C30 -> 1850 | H30: =G30*12 -> 22200 | I30: =H30/E30 -> 40.659341 | J30: =I30/12 -> 3.3882784
B31: 1BR – B (Mid) | C31: 21 | D31: 585 | E31: =C31*D31 -> 12285 | F31: 1950 | G31: =F31*C31 -> 40950 | H31: =G31*12 -> 491400 | I31: =H31/E31 -> 40 | J31: =I31/12 -> 3.3333333
B32: 1BR – C (Large) | C32: 0 | D32: 713 | E32: =C32*D32 -> 0 | F32: 2100 | G32: =F32*C32 -> 0 | H32: =G32*12 -> 0 | I32: =H32/E32 -> #DIV/0! | J32: =I32/12 -> #DIV/0!
B33: 2BR – A (Compact) | C33: 38 | D33: 825 | E33: =C33*D33 -> 31350 | F33: 2850 | G33: =F33*C33 -> 108300 | H33: =G33*12 -> 1299600 | I33: =H33/E33 -> 41.454545 | J33: =I33/12 -> 3.4545455
B34: 2BR – B (Large) | C34: 0 | D34: 996 | E34: =C34*D34 -> 0 | F34: 2850 | G34: =F34*C34 -> 0 | H34: =G34*12 -> 0 | I34: =H34/E34 -> #DIV/0! | J34: =I34/12 -> #DIV/0!
B35: Total / Average | C35: =SUM(C30:C34) -> 60 | D35: =E35/C35 -> 736.35 | E35: =SUM(E30:E34) -> 44181 | G35: =SUM(G30:G34) -> 151100 | H35: =SUM(H30:H34) -> 1813200
B37: affordable | C37: # Units | D37: Avg SF | E37: Total SF | F37: Rent | G37: Total Rent income | H37: Yearly income | I37: yearly psf | J37: Montly $/SF
B38: 1BR – A (Compact) | C38: 2 | D38: 585 | E38: =D38*C38 -> 1170 | F38: 1244 | G38: =F38*C38 -> 2488 | H38: =G38*12 -> 29856 | I38: =H38/E38 -> 25.517949 | J38: =I38/12 -> 2.1264957
B39: 2BR – A (Compact) | C39: 4 | D39: 850 | E39: =D39*C39 -> 3400 | F39: 1450 | G39: =F39*C39 -> 5800 | H39: =G39*12 -> 69600 | I39: =H39/E39 -> 20.470588 | J39: =I39/12 -> 1.7058824
C40: =SUM(C38:C39) -> 6 | E40: =SUM(E38:E39) -> 4570 | H40: =SUM(H38:H39) -> 99456
C42: =C40+C35 -> 66 | E42: =E40+E35 -> 48751 | H42: =H40+H35 -> 1912656
E43: =E42/C42 -> 738.65152

Sheet Construction Costs
B2: Land Costs
B3: Total Land Costs | E3: =Assumptions!F9 -> 3500000
B5: Hard Costs | H5: Cost per unit
E6: Total | F6: $/GSF | G6: $/NSF
B7: Hard Costs apartments | E7: =H7*Assumptions!C29 -> 16500000 | F7: =E7/Assumptions!D20 -> 155.57411 | G7: =E7/Assumptions!F17 -> 338.4546 | H7: 250000
B8: Hard Costs podium | E8: =H8*Assumptions!F30 -> 1890000 | F8: =E8/Assumptions!D18 -> 55.588235 | H8: 30000
B9: FF&E | E9: 200000
B10: Contingency | C10: 0.05 | D10: HC | E10: =SUM(E7:E9)*C10 -> 929500
B11: Total | E11: =SUM(E7:E10) -> 19519500 | F11: =E11/Assumptions!D20 -> 184.04417 | G11: =E11/Assumptions!$F$20 -> 367.24615 | H11: =E11/161 -> 121239.13
B13: Soft Costs | I13: Impact Fees
E14: $ | F14: $/GSF | G14: $/NSF | I14: Parkland Dedication | J14: =4700*Assumptions!C29 -> 310200
B15: Architects/Engineers | E15: =950000 -> 950000 | F15: =E15/Assumptions!$D$20 -> 8.9572973 | G15: =E15/Assumptions!$F$20 -> 17.873605 | I15: Austin City Impact Fee | J15: 30000
B16: Impact Fees | E16: =J17 -> 350200 | F16: =E16/Assumptions!$D$20 -> 3.3019426 | G16: =E16/Assumptions!$F$20 -> 6.5887754 | I16: Waste Water Impact Fee | J16: 10000
B17: Permits & Expediting | E17: 150000 | F17: =E17/Assumptions!$D$20 -> 1.4143101 | G17: =E17/Assumptions!$F$20 -> 2.8221482 | I17: Total | J17: =SUM(J14:J16) -> 350200
B18: Supervision, Local Partner Expenses, and Investor Relations | E18: 350000 | F18: =E18/Assumptions!$D$20 -> 3.3000569 | G18: =E18/Assumptions!$F$20 -> 6.5850125
B19: Inspections and Testing | E19: 100000 | F19: =E19/Assumptions!$D$20 -> 0.9428734 | G19: =E19/Assumptions!$F$20 -> 1.8814321
B20: Professional/Legal Fees | E20: 75000 | F20: =E20/Assumptions!$D$20 -> 0.70715505 | G20: =E20/Assumptions!$F$20 -> 1.4110741
B21: Owners Rep | E21: 250000 | F21: =E21/Assumptions!$D$20 -> 2.3571835 | G21: =E21/Assumptions!$F$20 -> 4.7035804
B22: Audit and Reporting | E22: 50000 | F22: =E22/Assumptions!$D$20 -> 0.4714367 | G22: =E22/Assumptions!$F$20 -> 0.94071607
B23: Marketing / Model Unit | E23: 70000 | F23: =E23/Assumptions!$D$20 -> 0.66001138 | G23: =E23/Assumptions!$F$20 -> 1.3170025
B24: Insurance | E24: 100000 | F24: =E24/Assumptions!$D$20 -> 0.9428734 | G24: =E24/Assumptions!$F$20 -> 1.8814321
B25: RE Taxes During Construction** | C25: 53000 | D25: 2 | E25: =C25*D25 -> 106000 | F25: =E25/Assumptions!$D$20 -> 0.9994458 | G25: =E25/Assumptions!$F$20 -> 1.9943181 | H25: *First Year covered by tenant
B26: Retail Leasing Commission | C26: 0.06 | D26: 5 | E26: =C26*D26*Assumptions!K5*12*Assumptions!F16 -> 42768 | F26: =E26/Assumptions!$D$20 -> 0.40324809 | G26: =E26/Assumptions!$F$20 -> 0.8046509
B27: Retail Tenant Improvements | C27: 20 | D27: NSF | E27: =C27*Assumptions!F16 -> 88000 | F27: =E27/Assumptions!$D$20 -> 0.82972859 | G27: =E27/Assumptions!$F$20 -> 1.6556603
B28: Working Capital During Leasing Period | C28: 1.5 | D28: GSF | E28: =C28*Assumptions!D20 -> 159088.17 | F28: =E28/Assumptions!$D$20 -> 1.5 | G28: =E28/Assumptions!$F$20 -> 2.9931359
B29: Closing Costs | E29: ='Closing Costs'!E46 -> 681788.21 | F29: =E29/Assumptions!$D$20 -> 6.4283997 | G29: =E29/Assumptions!$F$20 -> 12.827383
B30: Contingency | C30: 0.05 | D30: SC | E30: =SUM(E15:E29,E35)*C30 -> 239675.87 | F30: =E30/Assumptions!$D$20 -> 2.25984 | G30: =E30/Assumptions!$F$20 -> 4.5093389
B31: Capitalized Interest | E31: =-'Draw Schedule'!D16 -> 2131440.8 | F31: =E31/Assumptions!$D$20 -> 20.096789 | G31: =E31/Assumptions!$F$20 -> 40.101613
B32: Capitalized Ground Rent | E32: =-'Draw Schedule'!D15 -> 0 | F32: =E32/Assumptions!$D$20 -> 0 | G32: =E32/Assumptions!$F$20 -> 0
B33: NOI Shortfall | E33: =-'Draw Schedule'!D14 -> 0 | F33: =E33/Assumptions!$D$20 -> 0 | G33: =E33/Assumptions!$F$20 -> 0
B34: Total Soft Costs Before Developer Fee | E34: =SUM(E15:E33) -> 5893961.1 | F34: =E34/Assumptions!$D$20 -> 55.572591 | G34: =E34/Assumptions!$F$20 -> 110.89088
B35: Developer Fee | C35: 0.05 | D35: HC and SC | E35: =C35*(E11+E34) -> 1270673.1 | F35: =E35/Assumptions!$D$20 -> 11.980838 | G35: =E35/Assumptions!$F$20 -> 23.906851
B36: Total Soft Costs | E36: =E34+E35 -> 7164634.1 | F36: =E36/Assumptions!$D$20 -> 67.553429 | G36: =E36/Assumptions!$F$20 -> 134.79773
B38: Total Costs | E38: =E3+E11+E36 -> 30184134 | F38: =E38/Assumptions!$D$20 -> 284.59817 | G38: =E38/Assumptions!$F$20 -> 567.894

Sheet Hard Costs
A5: Design | C5: 75000 | D5: =C5/Assumptions!$D$20 -> 0.70715505
A6: Mobilization | C6: 142000 | D6: =C6/Assumptions!$D$20 -> 1.3388802
A7: Concrete | B7: Podium | C7: 5000000 | D7: =C7/Assumptions!$D$20 -> 47.14367
B8: Residntial | C8: =40*11000*13 -> 5720000 | D8: =C8/Assumptions!$D$20 -> 53.932358
A9: Masonary | C9: =D9*Assumptions!$D$17 -> 417993.05 | D9: =2585706/335082 -> 7.7166365
A10: Metal | C10: =D10*Assumptions!$D$17 -> 135419.44 | D10: 2.5
A11: Carpentry | C11: =D11*Assumptions!$D$17 -> 1300026.7 | D11: 24
A12: Thermal moister protection | C12: =D12*Assumptions!$D$17 -> 297922.78 | D12: 5.5
A13: openings | C13: =D13*Assumptions!$D$17 -> 270838.89 | D13: 5
A14: Finishes | C14: =D14*Assumptions!$D$17 -> 758348.89 | D14: 14
A15: speciality | C15: =D15*Assumptions!$D$17 -> 54167.778 | D15: 1
A16: equipment | C16: =D16*Assumptions!$D$17 -> 135419.44 | D16: 2.5
A17: furnishing | C17: =D17*Assumptions!$D$17 -> 270838.89 | D17: 5
A18: special construction | C18: =D18*Assumptions!$D$17 -> 541677.78 | D18: 10
A19: elevators | C19: =D19*Assumptions!$D$17 -> 108335.56 | D19: 2
A20: fire suppression | C20: =D20*Assumptions!$D$17 -> 135419.44 | D20: 2.5
A21: plumbing | C21: =D21*Assumptions!$D$17 -> 487510 | D21: 9
... A30: Insurance | C30: =D30*Assumptions!$D$17 -> 108335.56 | D30: 2
A31: Subtotal | C31: =SUM(C5:C30) -> 17584287
A32: Contingency | B32: 0.05 | C32: =C31*B32 -> 879214.37
A33: GC Fee | B33: 0.1 | C33: =C31*B33 -> 1758428.7 | E33: GSF | F33: NGF
A34: Total | C34: =C31+C32+C33 -> 20221931 | E34: =C34/Assumptions!D20 -> 190.6672 | F34: =C34/Assumptions!F17 -> 414.80032

Sheet Closing Costs
B2: Land Closing
B3: Transaction Legal | E3: 7000
B4: Title Insurance | C4: 0.0015 | D4: of PP | E4: =C4*Assumptions!$F$9 -> 5250
B5: Acquisition Fee | C5: 0.02 | D5: of PP | E5: =C5*Assumptions!$F$9 -> 70000
B6: Real Estate Broker | C6: 0.01 | D6: of PP | E6: =C6*Assumptions!$F$9 -> 35000
B7: Due Diligence | E7: 30000
B8: Total | E8: =SUM(E3:E7) -> 147250
B10: Acquisition Loan Closing
B11: Bank Fee | C11: 0 | D11: of Mtg | E11: =C11*Assumptions!$Q$4 -> 0
B12: Mortgage Broker Fee | C12: 0 | D12: of Mtg | E12: =C12*Assumptions!$Q$4 -> 0
B13: Mortgage Recording Tax | C13: 0 | D13: of Mtg | E13: =C13*Assumptions!$Q$4 -> 0
B14: Title Insurance | C14: 0 | D14: of Mtg | E14: =C14*Assumptions!$Q$4 -> 0
B15: Appraisal & Environmental | E15: 0
B16: Lender Legal | E16: 0
B17: General Loan Closing Costs | E17: 0
B18: Total | E18: =SUM(E11:E17) -> 0
B20: Construction Loan Closing
B21: Bank Fee | C21: 0.01 | D21: of Mtg | E21: =C21*Assumptions!$Q$11 -> 208881.01
B22: Mortgage Broker Fee | C22: 0.01 | D22: of Mtg | E22: =C22*Assumptions!$Q$11 -> 208881.01
B23: Mortgage Recording Tax | C23: 0.0005 | D23: of Mtg | E23: =C23*Assumptions!$Q$11 -> 10444.05
B24: Title Insurance | C24: 0.0015 | D24: of Mtg | E24: =C24*Assumptions!$Q$11 -> 31332.151
B25: Appraisal & Environmental | E25: 25000
B26: Lender Legal | E26: 25000
B27: General Loan Closing Costs | E27: 25000
B28: Total | E28: =SUM(E21:E27) -> 534538.21
B30: Mezzanine Loan Closing
B31: Mezz Bank Fee | C31: 0.01 | D31: of Mezz | E31: =C31*Assumptions!$Q$17 -> 0
B32: Mezz Broker Fee | C32: 0.005 | D32: of Mezz | E32: =C32*Assumptions!$Q$17 -> 0
B33: Title Insurance | C33: 0.0055 | D33: of Mezz | E33: =C33*Assumptions!$Q$17 -> 0
B34: Lender Legal | E34: 0
B35: General Closing Costs | E35: 0
B36: Total | E36: =SUM(E31:E35) -> 0
B38: Ground Lease Loan Closing
B39: Ground Lease Fee | C39: =IF(Assumptions!$Q$33="Yes",'Closing Costs'!H39,0) -> 0 | D39: of GL | E39: =IF(Assumptions!$Q$24="No",0,C39*Assumptions!$Q$25) -> 0
B40: Ground Lease Broker Fee | C40: 0.005 | D40: of GL | E40: =IF(Assumptions!$Q$24="No",0,C40*Assumptions!$Q$25) -> 0
B41: Title Insurance | C41: 0.0055 | D41: of GL | E41: =IF(Assumptions!$Q$24="No",0,C41*Assumptions!$Q$25) -> 0
B42: Ground Lease Legal | E42: 0
B43: General Loan Closing Costs | E43: 0
B44: Total | E44: =SUM(E39:E43) -> 0
B46: Total Closing Costs | E46: =E8+E18+E28+E36+E44 -> 681788.21
...

Sheet Taxes
B2: Taxes - Toomey Apartments - Austin, TX
B3: Land Purchase Price | E3: ='Construction Costs'!E3 -> 3500000
B4: Hard Costs | E4: ='Construction Costs'!E11 -> 19519500
B5: Soft Costs | C5: Include? | D5: Y | E5: =IF(D5="Y",'Construction Costs'!E36-E6-E7,0) -> 4351405.1
B6: Construction Interest | C6: Include? | D6: Y | E6: =IF(D5="Y",'Construction Costs'!E31+'Construction Costs'!E32,0) -> 2131440.8
B7: Financing Fees | C7: Include? | D7: Y | E7: =IF(D5="Y",'Construction Costs'!E29,0) -> 681788.21
B9: Assessment Percentage | E9: 0.7
B11: Assessed Value | E11: =SUM(E3:E7)*E9 -> 21128894
B13: Year 1 Millage Rates | E13: (All Millage Rates should be divided by 100)
B14: Travis County | E14: 0.375845
B15: City of Austin | E15: 0.524017
B16: Austin ISD | E16: 0.9252
B17: Travis County Healthcare Dist | E17: 0.118023
B18: Austin Comm College | E18: 0.1034
B19: blank | E19: 0
B20: blank | E20: 0
B21: Blank 1 | E21: 0
B22: Blank 2 | E22: 0
B23: Blank 3 | E23: 0
B24: Blank 4 | E24: 0
B25: Blank 5 | E25: 0
B26: Total | E26: =SUM(E14:E25) -> 2.046485
B28: Stabilized Tax Expense | E28: =E11*E26/100 -> 432399.64

Sheet Draw Schedule
B2: Monthly Cash Flows
B3: Month | D3: Total | F3: 1 | G3: =F3+1 -> 2 | H3: =G3+1 -> 3 | I3: =H3+1 -> 4 | J3: =I3+1 -> 5 | K3: =J3+1 -> 6 | L3: =K3+1 -> 7 | M3: =L3+1 -> 8 | N3: =M3+1 -> 9 | ... ET3: =ES3+1 -> 145
B4: Year | F4: =ROUNDUP(F3/12,0) -> 1 | G4: =ROUNDUP(G3/12,0) -> 1 | H4: =ROUNDUP(H3/12,0) -> 1 | I4: =ROUNDUP(I3/12,0) -> 1 | J4: =ROUNDUP(J3/12,0) -> 1 | K4: =ROUNDUP(K3/12,0) -> 1 | L4: =ROUNDUP(L3/12,0) -> 1 | M4: =ROUNDUP(M3/12,0) -> 1 | ... ET4: =ROUNDUP(ET3/12,0) -> 13
B5: Year Post TCO | F5: =IF(F6>=Assumptions!$F$38,ROUNDUP(YEARFRAC(Assumptions!$F$38-1,'Draw Schedule'!F6),0),0) -> 0 | G5: =IF(G6>=Assumptions!$F$38,ROUNDUP(YEARFRAC(Assumptions!$F$38-1,'Draw Schedule'!G6),0),0) -> 0 | H5: =IF(H6>=Assumptions!$F$38,ROUNDUP(YEARFRAC(Assumptions!$F$38-1,'Draw Schedule'!H6),0),0) -> 0 | I5: =IF(I6>=Assumptions!$F$38,ROUNDUP(YEARFRAC(Assumptions!$F$38-1,'Draw Schedule'!I6),0),0) -> 0 | J5: =IF(J6>=Assumptions!$F$38,ROUNDUP(YEARFRAC(Assumptions!$F$38-1,'Draw Schedule'!J6),0),0) -> 0 | K5: =IF(K6>=Assumptions!$F$38,ROUNDUP(YEARFRAC(Assumptions!$F$38-1,'Draw Schedule'!K6),0),0) -> 0 | L5: =IF(L6>=Assumptions!$F$38,ROUNDUP(YEARFRAC(Assumptions!$F$38-1,'Draw Schedule'!L6),0),0) -> 0 | M5: =IF(M6>=Assumptions!$F$38,ROUNDUP(YEARFRAC(Assumptions!$F$38-1,'Draw Schedule'!M6),0),0) -> 0 | ... ET5: =IF(ET6>=Assumptions!$F$38,ROUNDUP(YEARFRAC(Assumptions!$F$38-1,'Draw Schedule'!ET6),0),0) -> 10
B6: Date | F6: =Assumptions!F35 -> 46023 | G6: =EDATE(F6,1) -> 46054 | H6: =EDATE(G6,1) -> 46082 | I6: =EDATE(H6,1) -> 46113 | J6: =EDATE(I6,1) -> 46143 | K6: =EDATE(J6,1) -> 46174 | L6: =EDATE(K6,1) -> 46204 | M6: =EDATE(L6,1) -> 46235 | N6: =EDATE(M6,1) -> 46266 | ... ET6: =EDATE(ES6,1) -> 50406
B8: Uses
B9: Acquisition | D9: =SUM(F9:ET9) -> -3500000 | F9: =-IF(F$6=Assumptions!$F$35,Assumptions!$F$9,0) -> -3500000 | G9: =IF(G6=Assumptions!$F$35,Assumptions!$F$9,0) -> 0 | H9: =IF(H6=Assumptions!$F$35,Assumptions!$F$9,0) -> 0 | I9: =IF(I6=Assumptions!$F$35,Assumptions!$F$9,0) -> 0 | J9: =IF(J6=Assumptions!$F$35,Assumptions!$F$9,0) -> 0 | K9: =IF(K6=Assumptions!$F$35,Assumptions!$F$9,0) -> 0 | L9: =IF(L6=Assumptions!$F$35,Assumptions!$F$9,0) -> 0 | M9: =IF(M6=Assumptions!$F$35,Assumptions!$F$9,0) -> 0 | N9: =IF(N6=Assumptions!$F$35,Assumptions!$F$9,0) -> 0 | ... ET9: =IF(ET6=Assumptions!$F$35,Assumptions!$F$9,0) -> 0
B10: Closing Soft Costs | D10: =SUM(F10:ET10) -> -681788.21 | F10: =-(IF(F$6=Assumptions!$F$35,'Closing Costs'!$E$8,0)+IF(F$6=Assumptions!$P$5,'Closing Costs'!$E$18,0)+IF(F$6=Assumptions!$P$12,'Closing Costs'!$E$28,0)+IF(F$6=Assumptions!$P$18,'Closing Costs'!$E$36,0)+IF(F$6=Assumptions!$P$26,'Closing Costs'!$E$44,0)) -> -147250 | G10: =-(IF(G$6=Assumptions!$F$35,'Closing Costs'!$E$8,0)+IF(G$6=Assumptions!$P$5,'Closing Costs'!$E$18,0)+IF(G$6=Assumptions!$P$12,'Closing Costs'!$E$28,0)+IF(G$6=Assumptions!$P$18,'Closing Costs'!$E$36,0)+IF(G$6=Assumptions!$P$26,'Closing Costs'!$E$44,0)) -> 0 | H10: =-(IF(H$6=Assumptions!$F$35,'Closing Costs'!$E$8,0)+IF(H$6=Assumptions!$P$5,'Closing Costs'!$E$18,0)+IF(H$6=Assumptions!$P$12,'Closing Costs'!$E$28,0)+IF(H$6=Assumptions!$P$18,'Closing Costs'!$E$36,0)+IF(H$6=Assumptions!$P$26,'Closing Costs'!$E$44,0)) -> 0 | I10: =-(IF(I$6=Assumptions!$F$35,'Closing Costs'!$E$8,0)+IF(I$6=Assumptions!$P$5,'Closing Costs'!$E$18,0)+IF(I$6=Assumptions!$P$12,'Closing Costs'!$E$28,0)+IF(I$6=Assumptions!$P$18,'Closing Costs'!$E$36,0)+IF(I$6=Assumptions!$P$26,'Closing Costs'!$E$44,0)) -> 0 | J10: =-(IF(J$6=Assumptions!$F$35,'Closing Costs'!$E$8,0)+IF(J$6=Assumptions!$P$5,'Closing Costs'!$E$18,0)+IF(J$6=Assumptions!$P$12,'Closing Costs'!$E$28,0)+IF(J$6=Assumptions!$P$18,'Closing Costs'!$E$36,0)+IF(J$6=Assumptions!$P$26,'Closing Costs'!$E$44,0)) -> 0 | K10: =-(IF(K$6=Assumptions!$F$35,'Closing Costs'!$E$8,0)+IF(K$6=Assumptions!$P$5,'Closing Costs'!$E$18,0)+IF(K$6=Assumptions!$P$12,'Closing Costs'!$E$28,0)+IF(K$6=Assumptions!$P$18,'Closing Costs'!$E$36,0)+IF(K$6=Assumptions!$P$26,'Closing Costs'!$E$44,0)) -> 0 | L10: =-(IF(L$6=Assumptions!$F$35,'Closing Costs'!$E$8,0)+IF(L$6=Assumptions!$P$5,'Closing Costs'!$E$18,0)+IF(L$6=Assumptions!$P$12,'Closing Costs'!$E$28,0)+IF(L$6=Assumptions!$P$18,'Closing Costs'!$E$36,0)+IF(L$6=Assumptions!$P$26,'Closing Costs'!$E$44,0)) -> 0 | M10: =-(IF(M$6=Assumptions!$F$35,'Closing Costs'!$E$8,0)+IF(M$6=Assumptions!$P$5,'Closing Costs'!$E$18,0)+IF(M$6=Assumptions!$P$12,'Closing Costs'!$E$28,0)+IF(M$6=Assumptions!$P$18,'Closing Costs'!$E$36,0)+IF(M$6=Assumptions!$P$26,'Closing Costs'!$E$44,0)) -> 0 | ... ET10: =-(IF(ET$6=Assumptions!$F$35,'Closing Costs'!$E$8,0)+IF(ET$6=Assumptions!$P$5,'Closing Costs'!$E$18,0)+IF(ET$6=Assumptions!$P$12,'Closing Costs'!$E$28,0)+IF(ET$6=Assumptions!$P$18,'Closing Costs'!$E$36,0)+IF(ET$6=Assumptions!$P$26,'Closing Costs'!$E$44,0)) -> 0
B11: Construction Soft Costs | D11: =SUM(F11:ET11) -> -3080732 | F11: =-IF(F$3<=SUM(Assumptions!$F$36:$F$37),('Construction Costs'!$E$34-'Construction Costs'!$E$29-'Construction Costs'!$E$31-'Construction Costs'!$E$32-'Construction Costs'!$E$33)/SUM(Assumptions!$F$36:$F$37),0) -> -88020.915 | G11: =-IF(G$3<=SUM(Assumptions!$F$36:$F$37),('Construction Costs'!$E$34-'Construction Costs'!$E$29-'Construction Costs'!$E$31-'Construction Costs'!$E$32-'Construction Costs'!$E$33)/SUM(Assumptions!$F$36:$F$37),0) -> -88020.915 | H11: =-IF(H$3<=SUM(Assumptions!$F$36:$F$37),('Construction Costs'!$E$34-'Construction Costs'!$E$29-'Construction Costs'!$E$31-'Construction Costs'!$E$32-'Construction Costs'!$E$33)/SUM(Assumptions!$F$36:$F$37),0) -> -88020.915 | I11: =-IF(I$3<=SUM(Assumptions!$F$36:$F$37),('Construction Costs'!$E$34-'Construction Costs'!$E$29-'Construction Costs'!$E$31-'Construction Costs'!$E$32-'Construction Costs'!$E$33)/SUM(Assumptions!$F$36:$F$37),0) -> -88020.915 | J11: =-IF(J$3<=SUM(Assumptions!$F$36:$F$37),('Construction Costs'!$E$34-'Construction Costs'!$E$29-'Construction Costs'!$E$31-'Construction Costs'!$E$32-'Construction Costs'!$E$33)/SUM(Assumptions!$F$36:$F$37),0) -> -88020.915 | K11: =-IF(K$3<=SUM(Assumptions!$F$36:$F$37),('Construction Costs'!$E$34-'Construction Costs'!$E$29-'Construction Costs'!$E$31-'Construction Costs'!$E$32-'Construction Costs'!$E$33)/SUM(Assumptions!$F$36:$F$37),0) -> -88020.915 | L11: =-IF(L$3<=SUM(Assumptions!$F$36:$F$37),('Construction Costs'!$E$34-'Construction Costs'!$E$29-'Construction Costs'!$E$31-'Construction Costs'!$E$32-'Construction Costs'!$E$33)/SUM(Assumptions!$F$36:$F$37),0) -> -88020.915 | M11: =-IF(M$3<=SUM(Assumptions!$F$36:$F$37),('Construction Costs'!$E$34-'Construction Costs'!$E$29-'Construction Costs'!$E$31-'Construction Costs'!$E$32-'Construction Costs'!$E$33)/SUM(Assumptions!$F$36:$F$37),0) -> -88020.915 | ... ET11: =-IF(ET$3<=SUM(Assumptions!$F$36:$F$37),('Construction Costs'!$E$34-'Construction Costs'!$E$29-'Construction Costs'!$E$31-'Construction Costs'!$E$32-'Construction Costs'!$E$33)/SUM(Assumptions!$F$36:$F$37),0) -> 0
B12: Developer Fee Soft Cost | D12: =SUM(F12:ET12) -> -1270673.1 | F12: =-IF(F$3<=SUM(Assumptions!$F$36:$F$37),'Construction Costs'!$E$35/SUM(Assumptions!$F$36:$F$37),0) -> -36304.944 | G12: =-IF(G$3<=SUM(Assumptions!$F$36:$F$37),'Construction Costs'!$E$35/SUM(Assumptions!$F$36:$F$37),0) -> -36304.944 | H12: =-IF(H$3<=SUM(Assumptions!$F$36:$F$37),'Construction Costs'!$E$35/SUM(Assumptions!$F$36:$F$37),0) -> -36304.944 | I12: =-IF(I$3<=SUM(Assumptions!$F$36:$F$37),'Construction Costs'!$E$35/SUM(Assumptions!$F$36:$F$37),0) -> -36304.944 | J12: =-IF(J$3<=SUM(Assumptions!$F$36:$F$37),'Construction Costs'!$E$35/SUM(Assumptions!$F$36:$F$37),0) -> -36304.944 | K12: =-IF(K$3<=SUM(Assumptions!$F$36:$F$37),'Construction Costs'!$E$35/SUM(Assumptions!$F$36:$F$37),0) -> -36304.944 | L12: =-IF(L$3<=SUM(Assumptions!$F$36:$F$37),'Construction Costs'!$E$35/SUM(Assumptions!$F$36:$F$37),0) -> -36304.944 | M12: =-IF(M$3<=SUM(Assumptions!$F$36:$F$37),'Construction Costs'!$E$35/SUM(Assumptions!$F$36:$F$37),0) -> -36304.944 | ... ET12: =-IF(ET$3<=SUM(Assumptions!$F$36:$F$37),'Construction Costs'!$E$35/SUM(Assumptions!$F$36:$F$37),0) -> 0
B13: Hard Costs | D13: =SUM(F13:ET13) -> -19519500 | F13: =-IF(F$3<=Assumptions!$F$36,0,IF(F$3<=SUM(Assumptions!$F$36:$F$37),'Construction Costs'!$E$11/Assumptions!$F$37,0)) -> 0 | G13: =-IF(G$3<=Assumptions!$F$36,0,IF(G$3<=SUM(Assumptions!$F$36:$F$37),'Construction Costs'!$E$11/Assumptions!$F$37,0)) -> 0 | H13: =-IF(H$3<=Assumptions!$F$36,0,IF(H$3<=SUM(Assumptions!$F$36:$F$37),'Construction Costs'!$E$11/Assumptions!$F$37,0)) -> 0 | I13: =-IF(I$3<=Assumptions!$F$36,0,IF(I$3<=SUM(Assumptions!$F$36:$F$37),'Construction Costs'!$E$11/Assumptions!$F$37,0)) -> 0 | J13: =-IF(J$3<=Assumptions!$F$36,0,IF(J$3<=SUM(Assumptions!$F$36:$F$37),'Construction Costs'!$E$11/Assumptions!$F$37,0)) -> 0 | K13: =-IF(K$3<=Assumptions!$F$36,0,IF(K$3<=SUM(Assumptions!$F$36:$F$37),'Construction Costs'!$E$11/Assumptions!$F$37,0)) -> 0 | L13: =-IF(L$3<=Assumptions!$F$36,0,IF(L$3<=SUM(Assumptions!$F$36:$F$37),'Construction Costs'!$E$11/Assumptions!$F$37,0)) -> 0 | M13: =-IF(M$3<=Assumptions!$F$36,0,IF(M$3<=SUM(Assumptions!$F$36:$F$37),'Construction Costs'!$E$11/Assumptions!$F$37,0)) -> 0 | ... ET13: =-IF(ET$3<=Assumptions!$F$36,0,IF(ET$3<=SUM(Assumptions!$F$36:$F$37),'Construction Costs'!$E$11/Assumptions!$F$37,0)) -> 0
B14: NOI Shortfall | D14: =SUM(F14:ET14) -> 0 | F14: =IF(F63+F73<0,F63+F73,0) -> 0 | G14: =IF(G63+G73<0,G63+G73,0) -> 0 | H14: =IF(H63+H73<0,H63+H73,0) -> 0 | I14: =IF(I63+I73<0,I63+I73,0) -> 0 | J14: =IF(J63+J73<0,J63+J73,0) -> 0 | K14: =IF(K63+K73<0,K63+K73,0) -> 0 | L14: =IF(L63+L73<0,L63+L73,0) -> 0 | M14: =IF(M63+M73<0,M63+M73,0) -> 0 | ... ET14: =IF(ET63+ET73<0,ET63+ET73,0) -> 0
B15: Capitalized Ground Lease Rent | D15: =SUM(F15:ET15) -> 0 | F15: =-F141 -> 0 | G15: =-G141 -> 0 | H15: =-H141 -> 0 | I15: =-I141 -> 0 | J15: =-J141 -> 0 | K15: =-K141 -> 0 | L15: =-L141 -> 0 | M15: =-M141 -> 0 | ... ET15: =-ET141 -> 0
B16: Capitalized Interest | D16: =SUM(F16:ET16) -> -2131440.8 | F16: =-(F115+F125+F133) -> 0 | G16: =-(G115+G125+G133) -> -8750 | H16: =-(H115+H125+H133) -> -8750 | I16: =-(I115+I125+I133) -> -8750 | J16: =-(J115+J125+J133) -> -8750 | K16: =-(K115+K125+K133) -> -8750 | L16: =-(L115+L125+L133) -> -8750 | M16: =-(M115+M125+M133) -> -8750 | ... ET16: =-(ET115+ET125+ET133) -> 0
B17: Total Uses | D17: =SUM(F17:ET17) -> -30184134 | F17: =SUM(F9:F16) -> -3771575.9 | G17: =SUM(G9:G16) -> -133075.86 | H17: =SUM(H9:H16) -> -133075.86 | I17: =SUM(I9:I16) -> -133075.86 | J17: =SUM(J9:J16) -> -133075.86 | K17: =SUM(K9:K16) -> -133075.86 | L17: =SUM(L9:L16) -> -133075.86 | M17: =SUM(M9:M16) -> -133075.86 | ... ET17: =SUM(ET9:ET16) -> 0
B19: Sources
B20: Equity Contribution | D20: =SUM(F20:ET20) -> 7546033.5 | F20: =-F89 -> 2021575.9 | G20: =-G89 -> 133075.86 | H20: =-H89 -> 133075.86 | I20: =-I89 -> 133075.86 | J20: =-J89 -> 133075.86 | K20: =-K89 -> 133075.86 | L20: =-L89 -> 133075.86 | M20: =-M89 -> 133075.86 | ... ET20: =-ET89 -> 0
B21: Mezz Loan | D21: =SUM(F21:ET21) -> 0 | F21: =-F95 -> 0 | G21: =-G95 -> 0 | H21: =-H95 -> 0 | I21: =-I95 -> 0 | J21: =-J95 -> 0 | K21: =-K95 -> 0 | L21: =-L95 -> 0 | M21: =-M95 -> 0 | ... ET21: =-ET95 -> 0
B22: Ground Lease Contribution | D22: =SUM(F22:ET22) -> 0 | F22: =-F101 -> 0 | G22: =-G101 -> 0 | H22: =-H101 -> 0 | I22: =-I101 -> 0 | J22: =-J101 -> 0 | K22: =-K101 -> 0 | L22: =-L101 -> 0 | M22: =-M101 -> 0 | ... ET22: =-ET101 -> 0
B23: Senior Loan | D23: =SUM(F23:ET23) -> 22638101 | F23: =F114+F122 -> 1750000 | G23: =G114+G122 -> 0 | H23: =H114+H122 -> 0 | I23: =I114+I122 -> 0 | J23: =J114+J122 -> 0 | K23: =K114+K122 -> 0 | L23: =L114+L122 -> 0 | M23: =M114+M122 -> 0 | ... ET23: =ET114+ET122 -> 0
B24: Total Sources | D24: =SUM(F24:ET24) -> 30184134 | F24: =SUM(F19:F23) -> 3771575.9 | G24: =SUM(G19:G23) -> 133075.86 | H24: =SUM(H19:H23) -> 133075.86 | I24: =SUM(I19:I23) -> 133075.86 | J24: =SUM(J19:J23) -> 133075.86 | K24: =SUM(K19:K23) -> 133075.86 | L24: =SUM(L19:L23) -> 133075.86 | M24: =SUM(M19:M23) -> 133075.86 | ... ET24: =SUM(ET19:ET23) -> 0
B26: Check | D26: =D17+D24 -> -0.00024098903 | F26: =F17+F24 -> 0 | G26: =G17+G24 -> -8.7311491e-10 | H26: =H17+H24 -> -8.7311491e-10 | I26: =I17+I24 -> -8.7311491e-10 | J26: =J17+J24 -> -8.7311491e-10 | K26: =K17+K24 -> -8.7311491e-10 | L26: =L17+L24 -> -8.7311491e-10 | M26: =M17+M24 -> -8.7311491e-10 | ... ET26: =ET17+ET24 -> 0
B29: Proforma Rental Cash Flow
B30: Residential Occupancy
B31: Occupancy | F31: =E31+F32 -> 0 | G31: =F31+G32 -> 0 | H31: =G31+H32 -> 0 | I31: =H31+I32 -> 0 | J31: =I31+J32 -> 0 | K31: =J31+K32 -> 0 | L31: =K31+L32 -> 0 | M31: =L31+M32 -> 0 | ... ET31: =ES31+ET32 -> 0.95
B32: Lease Up | F32: =IF(F$6=Assumptions!$F$38,Assumptions!$K$17,IF(F$6>Assumptions!$F$38,MIN(Assumptions!$K$18,Assumptions!$K$19-SUM($E$32:E32)),0)) -> 0 | G32: =IF(G$6=Assumptions!$F$38,Assumptions!$K$17,IF(G$6>Assumptions!$F$38,MIN(Assumptions!$K$18,Assumptions!$K$19-SUM($E$32:F32)),0)) -> 0 | H32: =IF(H$6=Assumptions!$F$38,Assumptions!$K$17,IF(H$6>Assumptions!$F$38,MIN(Assumptions!$K$18,Assumptions!$K$19-SUM($E$32:G32)),0)) -> 0 | I32: =IF(I$6=Assumptions!$F$38,Assumptions!$K$17,IF(I$6>Assumptions!$F$38,MIN(Assumptions!$K$18,Assumptions!$K$19-SUM($E$32:H32)),0)) -> 0 | J32: =IF(J$6=Assumptions!$F$38,Assumptions!$K$17,IF(J$6>Assumptions!$F$38,MIN(Assumptions!$K$18,Assumptions!$K$19-SUM($E$32:I32)),0)) -> 0 | K32: =IF(K$6=Assumptions!$F$38,Assumptions!$K$17,IF(K$6>Assumptions!$F$38,MIN(Assumptions!$K$18,Assumptions!$K$19-SUM($E$32:J32)),0)) -> 0 | L32: =IF(L$6=Assumptions!$F$38,Assumptions!$K$17,IF(L$6>Assumptions!$F$38,MIN(Assumptions!$K$18,Assumptions!$K$19-SUM($E$32:K32)),0)) -> 0 | M32: =IF(M$6=Assumptions!$F$38,Assumptions!$K$17,IF(M$6>Assumptions!$F$38,MIN(Assumptions!$K$18,Assumptions!$K$19-SUM($E$32:L32)),0)) -> 0 | ... ET32: =IF(ET$6=Assumptions!$F$38,Assumptions!$K$17,IF(ET$6>Assumptions!$F$38,MIN(Assumptions!$K$18,Assumptions!$K$19-SUM($E$32:ES32)),0)) -> 0
B34: Retail Occupancy
B35: Occupancy | F35: =E35+F36 -> 0 | G35: =F35+G36 -> 0 | H35: =G35+H36 -> 0 | I35: =H35+I36 -> 0 | J35: =I35+J36 -> 0 | K35: =J35+K36 -> 0 | L35: =K35+L36 -> 0 | M35: =L35+M36 -> 0 | ... ET35: =ES35+ET36 -> 1
B36: Lease Up | F36: =IF(F$6=Assumptions!$F$38,Assumptions!$L$17,IF(F$6>Assumptions!$F$38,MIN(Assumptions!$L$18,Assumptions!$L$19-SUM($E$36:E36)),0)) -> 0 | G36: =IF(G$6=Assumptions!$F$38,Assumptions!$L$17,IF(G$6>Assumptions!$F$38,MIN(Assumptions!$L$18,Assumptions!$L$19-SUM($E$36:F36)),0)) -> 0 | H36: =IF(H$6=Assumptions!$F$38,Assumptions!$L$17,IF(H$6>Assumptions!$F$38,MIN(Assumptions!$L$18,Assumptions!$L$19-SUM($E$36:G36)),0)) -> 0 | I36: =IF(I$6=Assumptions!$F$38,Assumptions!$L$17,IF(I$6>Assumptions!$F$38,MIN(Assumptions!$L$18,Assumptions!$L$19-SUM($E$36:H36)),0)) -> 0 | J36: =IF(J$6=Assumptions!$F$38,Assumptions!$L$17,IF(J$6>Assumptions!$F$38,MIN(Assumptions!$L$18,Assumptions!$L$19-SUM($E$36:I36)),0)) -> 0 | K36: =IF(K$6=Assumptions!$F$38,Assumptions!$L$17,IF(K$6>Assumptions!$F$38,MIN(Assumptions!$L$18,Assumptions!$L$19-SUM($E$36:J36)),0)) -> 0 | L36: =IF(L$6=Assumptions!$F$38,Assumptions!$L$17,IF(L$6>Assumptions!$F$38,MIN(Assumptions!$L$18,Assumptions!$L$19-SUM($E$36:K36)),0)) -> 0 | M36: =IF(M$6=Assumptions!$F$38,Assumptions!$L$17,IF(M$6>Assumptions!$F$38,MIN(Assumptions!$L$18,Assumptions!$L$19-SUM($E$36:L36)),0)) -> 0 | ... ET36: =IF(ET$6=Assumptions!$F$38,Assumptions!$L$17,IF(ET$6>Assumptions!$F$38,MIN(Assumptions!$L$18,Assumptions!$L$19-SUM($E$36:ES36)),0)) -> 0
B38: Rental Rates
B39: Residential Market/NSF (Trended) | F39: =IF(Assumptions!$L$8="Yes",IF(F$6>=Assumptions!$F$35,Assumptions!$K$4*(1+Assumptions!$L$4)^ROUNDDOWN(YEARFRAC(F$6,Assumptions!$F$35),0),0),IF(F$6>=Assumptions!$F$38,Assumptions!$K$4*(1+Assumptions!$L$4)^ROUNDDOWN(YEARFRAC(F$6,Assumptions!$F$38),0),0)) -> 3.2694304 | G39: =IF(Assumptions!$L$8="Yes",IF(G$6>=Assumptions!$F$35,Assumptions!$K$4*(1+Assumptions!$L$4)^ROUNDDOWN(YEARFRAC(G$6,Assumptions!$F$35),0),0),IF(G$6>=Assumptions!$F$38,Assumptions!$K$4*(1+Assumptions!$L$4)^ROUNDDOWN(YEARFRAC(G$6,Assumptions!$F$38),0),0)) -> 3.2694304 | H39: =IF(Assumptions!$L$8="Yes",IF(H$6>=Assumptions!$F$35,Assumptions!$K$4*(1+Assumptions!$L$4)^ROUNDDOWN(YEARFRAC(H$6,Assumptions!$F$35),0),0),IF(H$6>=Assumptions!$F$38,Assumptions!$K$4*(1+Assumptions!$L$4)^ROUNDDOWN(YEARFRAC(H$6,Assumptions!$F$38),0),0)) -> 3.2694304 | I39: =IF(Assumptions!$L$8="Yes",IF(I$6>=Assumptions!$F$35,Assumptions!$K$4*(1+Assumptions!$L$4)^ROUNDDOWN(YEARFRAC(I$6,Assumptions!$F$35),0),0),IF(I$6>=Assumptions!$F$38,Assumptions!$K$4*(1+Assumptions!$L$4)^ROUNDDOWN(YEARFRAC(I$6,Assumptions!$F$38),0),0)) -> 3.2694304 | J39: =IF(Assumptions!$L$8="Yes",IF(J$6>=Assumptions!$F$35,Assumptions!$K$4*(1+Assumptions!$L$4)^ROUNDDOWN(YEARFRAC(J$6,Assumptions!$F$35),0),0),IF(J$6>=Assumptions!$F$38,Assumptions!$K$4*(1+Assumptions!$L$4)^ROUNDDOWN(YEARFRAC(J$6,Assumptions!$F$38),0),0)) -> 3.2694304 | K39: =IF(Assumptions!$L$8="Yes",IF(K$6>=Assumptions!$F$35,Assumptions!$K$4*(1+Assumptions!$L$4)^ROUNDDOWN(YEARFRAC(K$6,Assumptions!$F$35),0),0),IF(K$6>=Assumptions!$F$38,Assumptions!$K$4*(1+Assumptions!$L$4)^ROUNDDOWN(YEARFRAC(K$6,Assumptions!$F$38),0),0)) -> 3.2694304 | L39: =IF(Assumptions!$L$8="Yes",IF(L$6>=Assumptions!$F$35,Assumptions!$K$4*(1+Assumptions!$L$4)^ROUNDDOWN(YEARFRAC(L$6,Assumptions!$F$35),0),0),IF(L$6>=Assumptions!$F$38,Assumptions!$K$4*(1+Assumptions!$L$4)^ROUNDDOWN(YEARFRAC(L$6,Assumptions!$F$38),0),0)) -> 3.2694304 | M39: =IF(Assumptions!$L$8="Yes",IF(M$6>=Assumptions!$F$35,Assumptions!$K$4*(1+Assumptions!$L$4)^ROUNDDOWN(YEARFRAC(M$6,Assumptions!$F$35),0),0),IF(M$6>=Assumptions!$F$38,Assumptions!$K$4*(1+Assumptions!$L$4)^ROUNDDOWN(YEARFRAC(M$6,Assumptions!$F$38),0),0)) -> 3.2694304 | ... ET39: =IF(Assumptions!$L$8="Yes",IF(ET$6>=Assumptions!$F$35,Assumptions!$K$4*(1+Assumptions!$L$4)^ROUNDDOWN(YEARFRAC(ET$6,Assumptions!$F$35),0),0),IF(ET$6>=Assumptions!$F$38,Assumptions!$K$4*(1+Assumptions!$L$4)^ROUNDDOWN(YEARFRAC(ET$6,Assumptions!$F$38),0),0)) -> 4.6614259
B40: Retail/NSF | F40: =IF(F$6>=Assumptions!$F$38,Assumptions!$K$5*(1+Assumptions!$L$5)^ROUNDDOWN(YEARFRAC(F$6,Assumptions!$F$38),0),0) -> 0 | G40: =IF(G$6>=Assumptions!$F$38,Assumptions!$K$5*(1+Assumptions!$L$5)^ROUNDDOWN(YEARFRAC(G$6,Assumptions!$F$38),0),0) -> 0 | H40: =IF(H$6>=Assumptions!$F$38,Assumptions!$K$5*(1+Assumptions!$L$5)^ROUNDDOWN(YEARFRAC(H$6,Assumptions!$F$38),0),0) -> 0 | I40: =IF(I$6>=Assumptions!$F$38,Assumptions!$K$5*(1+Assumptions!$L$5)^ROUNDDOWN(YEARFRAC(I$6,Assumptions!$F$38),0),0) -> 0 | J40: =IF(J$6>=Assumptions!$F$38,Assumptions!$K$5*(1+Assumptions!$L$5)^ROUNDDOWN(YEARFRAC(J$6,Assumptions!$F$38),0),0) -> 0 | K40: =IF(K$6>=Assumptions!$F$38,Assumptions!$K$5*(1+Assumptions!$L$5)^ROUNDDOWN(YEARFRAC(K$6,Assumptions!$F$38),0),0) -> 0 | L40: =IF(L$6>=Assumptions!$F$38,Assumptions!$K$5*(1+Assumptions!$L$5)^ROUNDDOWN(YEARFRAC(L$6,Assumptions!$F$38),0),0) -> 0 | M40: =IF(M$6>=Assumptions!$F$38,Assumptions!$K$5*(1+Assumptions!$L$5)^ROUNDDOWN(YEARFRAC(M$6,Assumptions!$F$38),0),0) -> 0 | ... ET40: =IF(ET$6>=Assumptions!$F$38,Assumptions!$K$5*(1+Assumptions!$L$5)^ROUNDDOWN(YEARFRAC(ET$6,Assumptions!$F$38),0),0) -> 3.5228876
B41: Parking/Spot | F41: =IF(F$6>=Assumptions!$F$38,Assumptions!$K$6*(1+Assumptions!$L$6)^ROUNDDOWN(YEARFRAC(F$6,Assumptions!$F$38),0),0) -> 0 | G41: =IF(G$6>=Assumptions!$F$38,Assumptions!$K$6*(1+Assumptions!$L$6)^ROUNDDOWN(YEARFRAC(G$6,Assumptions!$F$38),0),0) -> 0 | H41: =IF(H$6>=Assumptions!$F$38,Assumptions!$K$6*(1+Assumptions!$L$6)^ROUNDDOWN(YEARFRAC(H$6,Assumptions!$F$38),0),0) -> 0 | I41: =IF(I$6>=Assumptions!$F$38,Assumptions!$K$6*(1+Assumptions!$L$6)^ROUNDDOWN(YEARFRAC(I$6,Assumptions!$F$38),0),0) -> 0 | J41: =IF(J$6>=Assumptions!$F$38,Assumptions!$K$6*(1+Assumptions!$L$6)^ROUNDDOWN(YEARFRAC(J$6,Assumptions!$F$38),0),0) -> 0 | K41: =IF(K$6>=Assumptions!$F$38,Assumptions!$K$6*(1+Assumptions!$L$6)^ROUNDDOWN(YEARFRAC(K$6,Assumptions!$F$38),0),0) -> 0 | L41: =IF(L$6>=Assumptions!$F$38,Assumptions!$K$6*(1+Assumptions!$L$6)^ROUNDDOWN(YEARFRAC(L$6,Assumptions!$F$38),0),0) -> 0 | M41: =IF(M$6>=Assumptions!$F$38,Assumptions!$K$6*(1+Assumptions!$L$6)^ROUNDDOWN(YEARFRAC(M$6,Assumptions!$F$38),0),0) -> 0 | ... ET41: =IF(ET$6>=Assumptions!$F$38,Assumptions!$K$6*(1+Assumptions!$L$6)^ROUNDDOWN(YEARFRAC(ET$6,Assumptions!$F$38),0),0) -> 0
B42: Misc Income/Unit | F42: =IF(F$6>=Assumptions!$F$38,Assumptions!$K$7*(1+Assumptions!$L$7)^ROUNDDOWN(YEARFRAC(F$6,Assumptions!$F$38),0),0) -> 0 | G42: =IF(G$6>=Assumptions!$F$38,Assumptions!$K$7*(1+Assumptions!$L$7)^ROUNDDOWN(YEARFRAC(G$6,Assumptions!$F$38),0),0) -> 0 | H42: =IF(H$6>=Assumptions!$F$38,Assumptions!$K$7*(1+Assumptions!$L$7)^ROUNDDOWN(YEARFRAC(H$6,Assumptions!$F$38),0),0) -> 0 | I42: =IF(I$6>=Assumptions!$F$38,Assumptions!$K$7*(1+Assumptions!$L$7)^ROUNDDOWN(YEARFRAC(I$6,Assumptions!$F$38),0),0) -> 0 | J42: =IF(J$6>=Assumptions!$F$38,Assumptions!$K$7*(1+Assumptions!$L$7)^ROUNDDOWN(YEARFRAC(J$6,Assumptions!$F$38),0),0) -> 0 | K42: =IF(K$6>=Assumptions!$F$38,Assumptions!$K$7*(1+Assumptions!$L$7)^ROUNDDOWN(YEARFRAC(K$6,Assumptions!$F$38),0),0) -> 0 | L42: =IF(L$6>=Assumptions!$F$38,Assumptions!$K$7*(1+Assumptions!$L$7)^ROUNDDOWN(YEARFRAC(L$6,Assumptions!$F$38),0),0) -> 0 | M42: =IF(M$6>=Assumptions!$F$38,Assumptions!$K$7*(1+Assumptions!$L$7)^ROUNDDOWN(YEARFRAC(M$6,Assumptions!$F$38),0),0) -> 0 | ... ET42: =IF(ET$6>=Assumptions!$F$38,Assumptions!$K$7*(1+Assumptions!$L$7)^ROUNDDOWN(YEARFRAC(ET$6,Assumptions!$F$38),0),0) -> 195.71598
B44: Gross Potential Residential Income | D44: =SUM(F44:ET44) -> 27371720 | F44: =F39*Assumptions!$F$17 -> 159388 | G44: =G39*Assumptions!$F$17 -> 159388 | H44: =H39*Assumptions!$F$17 -> 159388 | I44: =I39*Assumptions!$F$17 -> 159388 | J44: =J39*Assumptions!$F$17 -> 159388 | K44: =K39*Assumptions!$F$17 -> 159388 | L44: =L39*Assumptions!$F$17 -> 159388 | M44: =M39*Assumptions!$F$17 -> 159388 | ... ET44: =ET39*Assumptions!$F$17 -> 227249.18
B45: Gross Potential Parking Income | D45: =SUM(F45:ET45) -> 0 | F45: =F41*Assumptions!$F$30*Assumptions!$I$6 -> 0 | G45: =G41*Assumptions!$F$30*Assumptions!$I$6 -> 0 | H45: =H41*Assumptions!$F$30*Assumptions!$I$6 -> 0 | I45: =I41*Assumptions!$F$30*Assumptions!$I$6 -> 0 | J45: =J41*Assumptions!$F$30*Assumptions!$I$6 -> 0 | K45: =K41*Assumptions!$F$30*Assumptions!$I$6 -> 0 | L45: =L41*Assumptions!$F$30*Assumptions!$I$6 -> 0 | M45: =M41*Assumptions!$F$30*Assumptions!$I$6 -> 0 | ... ET45: =ET41*Assumptions!$F$30*Assumptions!$I$6 -> 0
B46: Gross Potential Misc Income | D46: =SUM(F46:ET46) -> 1232736.3 | F46: =F42*Assumptions!$C$29 -> 0 | G46: =G42*Assumptions!$C$29 -> 0 | H46: =H42*Assumptions!$C$29 -> 0 | I46: =I42*Assumptions!$C$29 -> 0 | J46: =J42*Assumptions!$C$29 -> 0 | K46: =K42*Assumptions!$C$29 -> 0 | L46: =L42*Assumptions!$C$29 -> 0 | M46: =M42*Assumptions!$C$29 -> 0 | ... ET46: =ET42*Assumptions!$C$29 -> 12917.255
B47: Vacancy Loss | D47: =SUM(F47:ET47) -> -7269318 | F47: =-SUM(F44:F46)*(1-F31) -> -159388 | G47: =-SUM(G44:G46)*(1-G31) -> -159388 | H47: =-SUM(H44:H46)*(1-H31) -> -159388 | I47: =-SUM(I44:I46)*(1-I31) -> -159388 | J47: =-SUM(J44:J46)*(1-J31) -> -159388 | K47: =-SUM(K44:K46)*(1-K31) -> -159388 | L47: =-SUM(L44:L46)*(1-L31) -> -159388 | M47: =-SUM(M44:M46)*(1-M31) -> -159388 | ... ET47: =-SUM(ET44:ET46)*(1-ET31) -> -12008.322
B48: Residential Concessions | D48: =SUM(F48:ET48) -> -69644.329 | F48: =IF(F6<=Assumptions!$F$39,SUM(F44:F47)*-Assumptions!$L$36/12,0) -> 0 | G48: =IF(G6<=Assumptions!$F$39,SUM(G44:G47)*-Assumptions!$L$36/12,0) -> 0 | H48: =IF(H6<=Assumptions!$F$39,SUM(H44:H47)*-Assumptions!$L$36/12,0) -> 0 | I48: =IF(I6<=Assumptions!$F$39,SUM(I44:I47)*-Assumptions!$L$36/12,0) -> 0 | J48: =IF(J6<=Assumptions!$F$39,SUM(J44:J47)*-Assumptions!$L$36/12,0) -> 0 | K48: =IF(K6<=Assumptions!$F$39,SUM(K44:K47)*-Assumptions!$L$36/12,0) -> 0 | L48: =IF(L6<=Assumptions!$F$39,SUM(L44:L47)*-Assumptions!$L$36/12,0) -> 0 | M48: =IF(M6<=Assumptions!$F$39,SUM(M44:M47)*-Assumptions!$L$36/12,0) -> 0 | ... ET48: =IF(ET6<=Assumptions!$F$39,SUM(ET44:ET47)*-Assumptions!$L$36/12,0) -> 0
B49: Effective Net Revenue | D49: =SUM(F49:ET49) -> 21265494 | F49: =SUM(F44:F48) -> 0 | G49: =SUM(G44:G48) -> 0 | H49: =SUM(H44:H48) -> 0 | I49: =SUM(I44:I48) -> 0 | J49: =SUM(J44:J48) -> 0 | K49: =SUM(K44:K48) -> 0 | L49: =SUM(L44:L48) -> 0 | M49: =SUM(M44:M48) -> 0 | ... ET49: =SUM(ET44:ET48) -> 228158.11
...

Sheet Levered CF
B2: Timeline | D2: 1 | E2: =D2+1 -> 2 | F2: =E2+1 -> 3 | G2: =F2+1 -> 4 | H2: =G2+1 -> 5 | I2: =H2+1 -> 6 | J2: =I2+1 -> 7 | K2: =J2+1 -> 8 | L2: =K2+1 -> 9 | M2: =L2+1 -> 10
B3: Uses Schedule | C3: Total | D3: =CONCATENATE(YEAR(Assumptions!$F$35)+D2-1," - ",YEAR(Assumptions!$F$35)+D2) -> 2026 - 2027 | E3: =CONCATENATE(YEAR(Assumptions!$F$35)+E2-1," - ",YEAR(Assumptions!$F$35)+E2) -> 2027 - 2028 | F3: =CONCATENATE(YEAR(Assumptions!$F$35)+F2-1," - ",YEAR(Assumptions!$F$35)+F2) -> 2028 - 2029 | G3: =CONCATENATE(YEAR(Assumptions!$F$35)+G2-1," - ",YEAR(Assumptions!$F$35)+G2) -> 2029 - 2030 | H3: =CONCATENATE(YEAR(Assumptions!$F$35)+H2-1," - ",YEAR(Assumptions!$F$35)+H2) -> 2030 - 2031 | I3: =CONCATENATE(YEAR(Assumptions!$F$35)+I2-1," - ",YEAR(Assumptions!$F$35)+I2) -> 2031 - 2032 | J3: =CONCATENATE(YEAR(Assumptions!$F$35)+J2-1," - ",YEAR(Assumptions!$F$35)+J2) -> 2032 - 2033 | K3: =CONCATENATE(YEAR(Assumptions!$F$35)+K2-1," - ",YEAR(Assumptions!$F$35)+K2) -> 2033 - 2034 | ... M3: =CONCATENATE(YEAR(Assumptions!$F$35)+M2-1," - ",YEAR(Assumptions!$F$35)+M2) -> 2035 - 2036
B4: Acquisition | C4: =SUM(D4:M4) -> -3500000 | D4: =SUMIF('Draw Schedule'!$F$4:$ET$4,'Levered CF'!D$2,'Draw Schedule'!$F$9:$ET$9) -> -3500000 | E4: =SUMIF('Draw Schedule'!$F$4:$ET$4,'Levered CF'!E$2,'Draw Schedule'!$F$9:$ET$9) -> 0 | F4: =SUMIF('Draw Schedule'!$F$4:$ET$4,'Levered CF'!F$2,'Draw Schedule'!$F$9:$ET$9) -> 0 | G4: =SUMIF('Draw Schedule'!$F$4:$ET$4,'Levered CF'!G$2,'Draw Schedule'!$F$9:$ET$9) -> 0 | H4: =SUMIF('Draw Schedule'!$F$4:$ET$4,'Levered CF'!H$2,'Draw Schedule'!$F$9:$ET$9) -> 0 | I4: =SUMIF('Draw Schedule'!$F$4:$ET$4,'Levered CF'!I$2,'Draw Schedule'!$F$9:$ET$9) -> 0 | J4: =SUMIF('Draw Schedule'!$F$4:$ET$4,'Levered CF'!J$2,'Draw Schedule'!$F$9:$ET$9) -> 0 | K4: =SUMIF('Draw Schedule'!$F$4:$ET$4,'Levered CF'!K$2,'Draw Schedule'!$F$9:$ET$9) -> 0 | ... M4: =SUMIF('Draw Schedule'!$F$4:$ET$4,'Levered CF'!M$2,'Draw Schedule'!$F$9:$ET$9) -> 0
B5: Soft Costs | C5: =SUM(D5:M5) -> -5033193.3 | D5: =SUMIF('Draw Schedule'!$F$4:$ET$4,'Levered CF'!D$2,'Draw Schedule'!$F$10:$ET$10)+SUMIF('Draw Schedule'!$F$4:$ET$4,'Levered CF'!D$2,'Draw Schedule'!$F$11:$ET$11)+SUMIF('Draw Schedule'!$F$4:$ET$4,'Levered CF'!D$2,'Draw Schedule'!$F$12:$ET$12) -> -1639160.3 | E5: =SUMIF('Draw Schedule'!$F$4:$ET$4,'Levered CF'!E$2,'Draw Schedule'!$F$10:$ET$10)+SUMIF('Draw Schedule'!$F$4:$ET$4,'Levered CF'!E$2,'Draw Schedule'!$F$11:$ET$11)+SUMIF('Draw Schedule'!$F$4:$ET$4,'Levered CF'!E$2,'Draw Schedule'!$F$12:$ET$12) -> -2026448.5 | F5: =SUMIF('Draw Schedule'!$F$4:$ET$4,'Levered CF'!F$2,'Draw Schedule'!$F$10:$ET$10)+SUMIF('Draw Schedule'!$F$4:$ET$4,'Levered CF'!F$2,'Draw Schedule'!$F$11:$ET$11)+SUMIF('Draw Schedule'!$F$4:$ET$4,'Levered CF'!F$2,'Draw Schedule'!$F$12:$ET$12) -> -1367584.5 | G5: =SUMIF('Draw Schedule'!$F$4:$ET$4,'Levered CF'!G$2,'Draw Schedule'!$F$10:$ET$10)+SUMIF('Draw Schedule'!$F$4:$ET$4,'Levered CF'!G$2,'Draw Schedule'!$F$11:$ET$11)+SUMIF('Draw Schedule'!$F$4:$ET$4,'Levered CF'!G$2,'Draw Schedule'!$F$12:$ET$12) -> 0 | H5: =SUMIF('Draw Schedule'!$F$4:$ET$4,'Levered CF'!H$2,'Draw Schedule'!$F$10:$ET$10)+SUMIF('Draw Schedule'!$F$4:$ET$4,'Levered CF'!H$2,'Draw Schedule'!$F$11:$ET$11)+SUMIF('Draw Schedule'!$F$4:$ET$4,'Levered CF'!H$2,'Draw Schedule'!$F$12:$ET$12) -> 0 | I5: =SUMIF('Draw Schedule'!$F$4:$ET$4,'Levered CF'!I$2,'Draw Schedule'!$F$10:$ET$10)+SUMIF('Draw Schedule'!$F$4:$ET$4,'Levered CF'!I$2,'Draw Schedule'!$F$11:$ET$11)+SUMIF('Draw Schedule'!$F$4:$ET$4,'Levered CF'!I$2,'Draw Schedule'!$F$12:$ET$12) -> 0 | J5: =SUMIF('Draw Schedule'!$F$4:$ET$4,'Levered CF'!J$2,'Draw Schedule'!$F$10:$ET$10)+SUMIF('Draw Schedule'!$F$4:$ET$4,'Levered CF'!J$2,'Draw Schedule'!$F$11:$ET$11)+SUMIF('Draw Schedule'!$F$4:$ET$4,'Levered CF'!J$2,'Draw Schedule'!$F$12:$ET$12) -> 0 | K5: =SUMIF('Draw Schedule'!$F$4:$ET$4,'Levered CF'!K$2,'Draw Schedule'!$F$10:$ET$10)+SUMIF('Draw Schedule'!$F$4:$ET$4,'Levered CF'!K$2,'Draw Schedule'!$F$11:$ET$11)+SUMIF('Draw Schedule'!$F$4:$ET$4,'Levered CF'!K$2,'Draw Schedule'!$F$12:$ET$12) -> 0 | ... M5: =SUMIF('Draw Schedule'!$F$4:$ET$4,'Levered CF'!M$2,'Draw Schedule'!$F$10:$ET$10)+SUMIF('Draw Schedule'!$F$4:$ET$4,'Levered CF'!M$2,'Draw Schedule'!$F$11:$ET$11)+SUMIF('Draw Schedule'!$F$4:$ET$4,'Levered CF'!M$2,'Draw Schedule'!$F$12:$ET$12) -> 0
B6: Hard Costs | C6: =SUM(D6:M6) -> -19519500 | D6: =SUMIF('Draw Schedule'!$F$4:$ET$4,'Levered CF'!D$2,'Draw Schedule'!$F$13:$ET$13) -> 0 | E6: =SUMIF('Draw Schedule'!$F$4:$ET$4,'Levered CF'!E$2,'Draw Schedule'!$F$13:$ET$13) -> -8783775 | F6: =SUMIF('Draw Schedule'!$F$4:$ET$4,'Levered CF'!F$2,'Draw Schedule'!$F$13:$ET$13) -> -10735725 | G6: =SUMIF('Draw Schedule'!$F$4:$ET$4,'Levered CF'!G$2,'Draw Schedule'!$F$13:$ET$13) -> 0 | H6: =SUMIF('Draw Schedule'!$F$4:$ET$4,'Levered CF'!H$2,'Draw Schedule'!$F$13:$ET$13) -> 0 | I6: =SUMIF('Draw Schedule'!$F$4:$ET$4,'Levered CF'!I$2,'Draw Schedule'!$F$13:$ET$13) -> 0 | J6: =SUMIF('Draw Schedule'!$F$4:$ET$4,'Levered CF'!J$2,'Draw Schedule'!$F$13:$ET$13) -> 0 | K6: =SUMIF('Draw Schedule'!$F$4:$ET$4,'Levered CF'!K$2,'Draw Schedule'!$F$13:$ET$13) -> 0 | ... M6: =SUMIF('Draw Schedule'!$F$4:$ET$4,'Levered CF'!M$2,'Draw Schedule'!$F$13:$ET$13) -> 0
B7: NOI Shortfall | C7: =SUM(D7:M7) -> 0 | D7: =SUMIF('Draw Schedule'!$F$4:$ET$4,'Levered CF'!D$2,'Draw Schedule'!$F$14:$ET$14) -> 0 | E7: =SUMIF('Draw Schedule'!$F$4:$ET$4,'Levered CF'!E$2,'Draw Schedule'!$F$14:$ET$14) -> 0 | F7: =SUMIF('Draw Schedule'!$F$4:$ET$4,'Levered CF'!F$2,'Draw Schedule'!$F$14:$ET$14) -> 0 | G7: =SUMIF('Draw Schedule'!$F$4:$ET$4,'Levered CF'!G$2,'Draw Schedule'!$F$14:$ET$14) -> 0 | H7: =SUMIF('Draw Schedule'!$F$4:$ET$4,'Levered CF'!H$2,'Draw Schedule'!$F$14:$ET$14) -> 0 | I7: =SUMIF('Draw Schedule'!$F$4:$ET$4,'Levered CF'!I$2,'Draw Schedule'!$F$14:$ET$14) -> 0 | J7: =SUMIF('Draw Schedule'!$F$4:$ET$4,'Levered CF'!J$2,'Draw Schedule'!$F$14:$ET$14) -> 0 | K7: =SUMIF('Draw Schedule'!$F$4:$ET$4,'Levered CF'!K$2,'Draw Schedule'!$F$14:$ET$14) -> 0 | ... M7: =SUMIF('Draw Schedule'!$F$4:$ET$4,'Levered CF'!M$2,'Draw Schedule'!$F$14:$ET$14) -> 0
B8: Capitalized Ground Rent | C8: =SUM(D8:M8) -> 0 | D8: =SUMIF('Draw Schedule'!$F$4:$ET$4,'Levered CF'!D$2,'Draw Schedule'!$F$15:$ET$15) -> 0 | E8: =SUMIF('Draw Schedule'!$F$4:$ET$4,'Levered CF'!E$2,'Draw Schedule'!$F$15:$ET$15) -> 0 | F8: =SUMIF('Draw Schedule'!$F$4:$ET$4,'Levered CF'!F$2,'Draw Schedule'!$F$15:$ET$15) -> 0 | G8: =SUMIF('Draw Schedule'!$F$4:$ET$4,'Levered CF'!G$2,'Draw Schedule'!$F$15:$ET$15) -> 0 | H8: =SUMIF('Draw Schedule'!$F$4:$ET$4,'Levered CF'!H$2,'Draw Schedule'!$F$15:$ET$15) -> 0 | I8: =SUMIF('Draw Schedule'!$F$4:$ET$4,'Levered CF'!I$2,'Draw Schedule'!$F$15:$ET$15) -> 0 | J8: =SUMIF('Draw Schedule'!$F$4:$ET$4,'Levered CF'!J$2,'Draw Schedule'!$F$15:$ET$15) -> 0 | K8: =SUMIF('Draw Schedule'!$F$4:$ET$4,'Levered CF'!K$2,'Draw Schedule'!$F$15:$ET$15) -> 0 | ... M8: =SUMIF('Draw Schedule'!$F$4:$ET$4,'Levered CF'!M$2,'Draw Schedule'!$F$15:$ET$15) -> 0
B9: Capitalized Interest | C9: =SUM(D9:M9) -> -2131440.8 | D9: =SUMIF('Draw Schedule'!$F$4:$ET$4,'Levered CF'!D$2,'Draw Schedule'!$F$16:$ET$16) -> -96250 | E9: =SUMIF('Draw Schedule'!$F$4:$ET$4,'Levered CF'!E$2,'Draw Schedule'!$F$16:$ET$16) -> -222785.59 | F9: =SUMIF('Draw Schedule'!$F$4:$ET$4,'Levered CF'!F$2,'Draw Schedule'!$F$16:$ET$16) -> -1139555.9 | G9: =SUMIF('Draw Schedule'!$F$4:$ET$4,'Levered CF'!G$2,'Draw Schedule'!$F$16:$ET$16) -> -500229.42 | H9: =SUMIF('Draw Schedule'!$F$4:$ET$4,'Levered CF'!H$2,'Draw Schedule'!$F$16:$ET$16) -> -113097.9 | I9: =SUMIF('Draw Schedule'!$F$4:$ET$4,'Levered CF'!I$2,'Draw Schedule'!$F$16:$ET$16) -> -59521.983 | J9: =SUMIF('Draw Schedule'!$F$4:$ET$4,'Levered CF'!J$2,'Draw Schedule'!$F$16:$ET$16) -> 0 | K9: =SUMIF('Draw Schedule'!$F$4:$ET$4,'Levered CF'!K$2,'Draw Schedule'!$F$16:$ET$16) -> 0 | ... M9: =SUMIF('Draw Schedule'!$F$4:$ET$4,'Levered CF'!M$2,'Draw Schedule'!$F$16:$ET$16) -> 0
B10: Total Uses | C10: =SUM(C4:C9) -> -30184134 | D10: =SUM(D4:D9) -> -5235410.3 | E10: =SUM(E4:E9) -> -11033009 | F10: =SUM(F4:F9) -> -13242865 | G10: =SUM(G4:G9) -> -500229.42 | H10: =SUM(H4:H9) -> -113097.9 | I10: =SUM(I4:I9) -> -59521.983 | J10: =SUM(J4:J9) -> 0 | ... M10: =SUM(M4:M9) -> 0
B12: Sources Schedule | C12: Total | D12: =D3 -> 2026 - 2027 | E12: =E3 -> 2027 - 2028 | F12: =F3 -> 2028 - 2029 | G12: =G3 -> 2029 - 2030 | H12: =H3 -> 2030 - 2031 | I12: =I3 -> 2031 - 2032 | J12: =J3 -> 2032 - 2033 | K12: =K3 -> 2033 - 2034 | ... M12: =M3 -> 2035 - 2036
B13: Equity Contribution | C13: =SUM(D13:M13) -> 7546033.5 | D13: =SUMIF('Draw Schedule'!$F$4:$ET$4,'Levered CF'!D$2,'Draw Schedule'!$F$20:$ET$20) -> 3485410.3 | E13: =SUMIF('Draw Schedule'!$F$4:$ET$4,'Levered CF'!E$2,'Draw Schedule'!$F$20:$ET$20) -> 4060623.2 | F13: =SUMIF('Draw Schedule'!$F$4:$ET$4,'Levered CF'!F$2,'Draw Schedule'!$F$20:$ET$20) -> 0 | G13: =SUMIF('Draw Schedule'!$F$4:$ET$4,'Levered CF'!G$2,'Draw Schedule'!$F$20:$ET$20) -> 0 | H13: =SUMIF('Draw Schedule'!$F$4:$ET$4,'Levered CF'!H$2,'Draw Schedule'!$F$20:$ET$20) -> 0 | I13: =SUMIF('Draw Schedule'!$F$4:$ET$4,'Levered CF'!I$2,'Draw Schedule'!$F$20:$ET$20) -> 0 | J13: =SUMIF('Draw Schedule'!$F$4:$ET$4,'Levered CF'!J$2,'Draw Schedule'!$F$20:$ET$20) -> 0 | K13: =SUMIF('Draw Schedule'!$F$4:$ET$4,'Levered CF'!K$2,'Draw Schedule'!$F$20:$ET$20) -> 0 | ... M13: =SUMIF('Draw Schedule'!$F$4:$ET$4,'Levered CF'!M$2,'Draw Schedule'!$F$20:$ET$20) -> 0
